[2024-11-28 17:48:35,806][flwr][WARNING] - Both server and strategy were provided, ignoring strategy
[2024-11-28 17:48:35,806][flwr][INFO] - Starting Flower simulation, config: ServerConfig(num_rounds=2, round_timeout=None)
[2024-11-28 17:48:41,175][flwr][INFO] - Flower VCE: Ray initialized with resources: {'CPU': 12.0, 'object_store_memory': 2873427148.0, 'memory': 5746854299.0, 'node:__internal_head__': 1.0, 'node:172.16.1.8': 1.0, 'GPU': 1.0, 'accelerator_type:G': 1.0}
[2024-11-28 17:48:41,175][flwr][INFO] - Flower VCE: Resources for each Virtual Client: {'num_cpus': 4, 'num_gpus': 1}
[2024-11-28 17:48:41,183][flwr][INFO] - Flower VCE: Creating VirtualClientEngineActorPool with 1 actors
[2024-11-28 17:48:41,183][flwr][INFO] - Initializing global parameters
[2024-11-28 17:48:41,183][flwr][INFO] - Requesting initial parameters from one random client
[2024-11-28 17:48:45,459][flwr][INFO] - Received initial parameters from one random client
[2024-11-28 17:48:45,459][flwr][INFO] - Evaluating initial parameters
[2024-11-28 17:48:49,937][flwr][INFO] - initial parameters (loss, other metrics): 0.6988210530244103, {'accuracy': 0.4806201550387597}
[2024-11-28 17:48:49,937][flwr][INFO] - FL starting
[2024-11-28 17:48:49,937][flwr][DEBUG] - fit_round 1: strategy sampled 2 clients (out of 60)
[2024-11-28 17:48:51,096][flwr][ERROR] - Traceback (most recent call last):
  File "/home/namvq/.cache/pypoetry/virtualenvs/niid-bench-orV17zke-py3.10/lib/python3.10/site-packages/flwr/simulation/ray_transport/ray_client_proxy.py", line 140, in _submit_job
    res = self.actor_pool.get_client_result(self.cid, timeout)
  File "/home/namvq/.cache/pypoetry/virtualenvs/niid-bench-orV17zke-py3.10/lib/python3.10/site-packages/flwr/simulation/ray_transport/ray_actor.py", line 402, in get_client_result
    return self._fetch_future_result(cid)
  File "/home/namvq/.cache/pypoetry/virtualenvs/niid-bench-orV17zke-py3.10/lib/python3.10/site-packages/flwr/simulation/ray_transport/ray_actor.py", line 288, in _fetch_future_result
    res_cid, res = ray.get(future)  # type: (str, ClientRes)
  File "/home/namvq/.cache/pypoetry/virtualenvs/niid-bench-orV17zke-py3.10/lib/python3.10/site-packages/ray/_private/auto_init_hook.py", line 24, in auto_init_wrapper
    return fn(*args, **kwargs)
  File "/home/namvq/.cache/pypoetry/virtualenvs/niid-bench-orV17zke-py3.10/lib/python3.10/site-packages/ray/_private/client_mode_hook.py", line 103, in wrapper
    return func(*args, **kwargs)
  File "/home/namvq/.cache/pypoetry/virtualenvs/niid-bench-orV17zke-py3.10/lib/python3.10/site-packages/ray/_private/worker.py", line 2524, in get
    raise value.as_instanceof_cause()
ray.exceptions.RayTaskError(ClientException): [36mray::DefaultActor.run()[39m (pid=57299, ip=172.16.1.8, actor_id=a0d91e71b45217e02a31afde01000000, repr=<flwr.simulation.ray_transport.ray_actor.DefaultActor object at 0x79451030b130>)
  File "/home/namvq/.cache/pypoetry/virtualenvs/niid-bench-orV17zke-py3.10/lib/python3.10/site-packages/flwr/simulation/ray_transport/ray_client_proxy.py", line 196, in fit
    return maybe_call_fit(
  File "/home/namvq/.cache/pypoetry/virtualenvs/niid-bench-orV17zke-py3.10/lib/python3.10/site-packages/flwr/client/client.py", line 217, in maybe_call_fit
    return client.fit(fit_ins)
  File "/home/namvq/.cache/pypoetry/virtualenvs/niid-bench-orV17zke-py3.10/lib/python3.10/site-packages/flwr/client/app.py", line 333, in _fit
    results = self.numpy_client.fit(parameters, ins.config)  # type: ignore
  File "/media/namvq/Data/code_flwr/niid_custom/niid_bench/niid_bench/client_fedprox.py", line 55, in fit
    self.set_parameters(parameters)
  File "/media/namvq/Data/code_flwr/niid_custom/niid_bench/niid_bench/client_fedprox.py", line 50, in set_parameters
    state_dict = OrderedDict({k: torch.from_numpy(np.copy(v)) for k, v in params_dict})
  File "/media/namvq/Data/code_flwr/niid_custom/niid_bench/niid_bench/client_fedprox.py", line 50, in <dictcomp>
    state_dict = OrderedDict({k: torch.from_numpy(np.copy(v)) for k, v in params_dict})
NameError: name 'np' is not defined

The above exception was the direct cause of the following exception:

[36mray::DefaultActor.run()[39m (pid=57299, ip=172.16.1.8, actor_id=a0d91e71b45217e02a31afde01000000, repr=<flwr.simulation.ray_transport.ray_actor.DefaultActor object at 0x79451030b130>)
  File "/home/namvq/.cache/pypoetry/virtualenvs/niid-bench-orV17zke-py3.10/lib/python3.10/site-packages/flwr/simulation/ray_transport/ray_actor.py", line 72, in run
    raise ClientException(str(message)) from ex
flwr.simulation.ray_transport.ray_actor.ClientException: 
>>>>>>>A ClientException occurred.('\n\tSomething went wrong when running your client workload.\n\tClient 36 crashed when the DefaultActor was running its workload.\n\tException triggered on the client side: Traceback (most recent call last):\n  File "/home/namvq/.cache/pypoetry/virtualenvs/niid-bench-orV17zke-py3.10/lib/python3.10/site-packages/flwr/simulation/ray_transport/ray_actor.py", line 60, in run\n    job_results = job_fn()\n  File "/home/namvq/.cache/pypoetry/virtualenvs/niid-bench-orV17zke-py3.10/lib/python3.10/site-packages/flwr/simulation/ray_transport/ray_client_proxy.py", line 196, in fit\n    return maybe_call_fit(\n  File "/home/namvq/.cache/pypoetry/virtualenvs/niid-bench-orV17zke-py3.10/lib/python3.10/site-packages/flwr/client/client.py", line 217, in maybe_call_fit\n    return client.fit(fit_ins)\n  File "/home/namvq/.cache/pypoetry/virtualenvs/niid-bench-orV17zke-py3.10/lib/python3.10/site-packages/flwr/client/app.py", line 333, in _fit\n    results = self.numpy_client.fit(parameters, ins.config)  # type: ignore\n  File "/media/namvq/Data/code_flwr/niid_custom/niid_bench/niid_bench/client_fedprox.py", line 55, in fit\n    self.set_parameters(parameters)\n  File "/media/namvq/Data/code_flwr/niid_custom/niid_bench/niid_bench/client_fedprox.py", line 50, in set_parameters\n    state_dict = OrderedDict({k: torch.from_numpy(np.copy(v)) for k, v in params_dict})\n  File "/media/namvq/Data/code_flwr/niid_custom/niid_bench/niid_bench/client_fedprox.py", line 50, in <dictcomp>\n    state_dict = OrderedDict({k: torch.from_numpy(np.copy(v)) for k, v in params_dict})\nNameError: name \'np\' is not defined\n',)

[2024-11-28 17:48:51,096][flwr][ERROR] - [36mray::DefaultActor.run()[39m (pid=57299, ip=172.16.1.8, actor_id=a0d91e71b45217e02a31afde01000000, repr=<flwr.simulation.ray_transport.ray_actor.DefaultActor object at 0x79451030b130>)
  File "/home/namvq/.cache/pypoetry/virtualenvs/niid-bench-orV17zke-py3.10/lib/python3.10/site-packages/flwr/simulation/ray_transport/ray_client_proxy.py", line 196, in fit
    return maybe_call_fit(
  File "/home/namvq/.cache/pypoetry/virtualenvs/niid-bench-orV17zke-py3.10/lib/python3.10/site-packages/flwr/client/client.py", line 217, in maybe_call_fit
    return client.fit(fit_ins)
  File "/home/namvq/.cache/pypoetry/virtualenvs/niid-bench-orV17zke-py3.10/lib/python3.10/site-packages/flwr/client/app.py", line 333, in _fit
    results = self.numpy_client.fit(parameters, ins.config)  # type: ignore
  File "/media/namvq/Data/code_flwr/niid_custom/niid_bench/niid_bench/client_fedprox.py", line 55, in fit
    self.set_parameters(parameters)
  File "/media/namvq/Data/code_flwr/niid_custom/niid_bench/niid_bench/client_fedprox.py", line 50, in set_parameters
    state_dict = OrderedDict({k: torch.from_numpy(np.copy(v)) for k, v in params_dict})
  File "/media/namvq/Data/code_flwr/niid_custom/niid_bench/niid_bench/client_fedprox.py", line 50, in <dictcomp>
    state_dict = OrderedDict({k: torch.from_numpy(np.copy(v)) for k, v in params_dict})
NameError: name 'np' is not defined

The above exception was the direct cause of the following exception:

[36mray::DefaultActor.run()[39m (pid=57299, ip=172.16.1.8, actor_id=a0d91e71b45217e02a31afde01000000, repr=<flwr.simulation.ray_transport.ray_actor.DefaultActor object at 0x79451030b130>)
  File "/home/namvq/.cache/pypoetry/virtualenvs/niid-bench-orV17zke-py3.10/lib/python3.10/site-packages/flwr/simulation/ray_transport/ray_actor.py", line 72, in run
    raise ClientException(str(message)) from ex
flwr.simulation.ray_transport.ray_actor.ClientException: 
>>>>>>>A ClientException occurred.('\n\tSomething went wrong when running your client workload.\n\tClient 36 crashed when the DefaultActor was running its workload.\n\tException triggered on the client side: Traceback (most recent call last):\n  File "/home/namvq/.cache/pypoetry/virtualenvs/niid-bench-orV17zke-py3.10/lib/python3.10/site-packages/flwr/simulation/ray_transport/ray_actor.py", line 60, in run\n    job_results = job_fn()\n  File "/home/namvq/.cache/pypoetry/virtualenvs/niid-bench-orV17zke-py3.10/lib/python3.10/site-packages/flwr/simulation/ray_transport/ray_client_proxy.py", line 196, in fit\n    return maybe_call_fit(\n  File "/home/namvq/.cache/pypoetry/virtualenvs/niid-bench-orV17zke-py3.10/lib/python3.10/site-packages/flwr/client/client.py", line 217, in maybe_call_fit\n    return client.fit(fit_ins)\n  File "/home/namvq/.cache/pypoetry/virtualenvs/niid-bench-orV17zke-py3.10/lib/python3.10/site-packages/flwr/client/app.py", line 333, in _fit\n    results = self.numpy_client.fit(parameters, ins.config)  # type: ignore\n  File "/media/namvq/Data/code_flwr/niid_custom/niid_bench/niid_bench/client_fedprox.py", line 55, in fit\n    self.set_parameters(parameters)\n  File "/media/namvq/Data/code_flwr/niid_custom/niid_bench/niid_bench/client_fedprox.py", line 50, in set_parameters\n    state_dict = OrderedDict({k: torch.from_numpy(np.copy(v)) for k, v in params_dict})\n  File "/media/namvq/Data/code_flwr/niid_custom/niid_bench/niid_bench/client_fedprox.py", line 50, in <dictcomp>\n    state_dict = OrderedDict({k: torch.from_numpy(np.copy(v)) for k, v in params_dict})\nNameError: name \'np\' is not defined\n',)
[2024-11-28 17:48:52,185][flwr][ERROR] - Traceback (most recent call last):
  File "/home/namvq/.cache/pypoetry/virtualenvs/niid-bench-orV17zke-py3.10/lib/python3.10/site-packages/flwr/simulation/ray_transport/ray_client_proxy.py", line 140, in _submit_job
    res = self.actor_pool.get_client_result(self.cid, timeout)
  File "/home/namvq/.cache/pypoetry/virtualenvs/niid-bench-orV17zke-py3.10/lib/python3.10/site-packages/flwr/simulation/ray_transport/ray_actor.py", line 402, in get_client_result
    return self._fetch_future_result(cid)
  File "/home/namvq/.cache/pypoetry/virtualenvs/niid-bench-orV17zke-py3.10/lib/python3.10/site-packages/flwr/simulation/ray_transport/ray_actor.py", line 288, in _fetch_future_result
    res_cid, res = ray.get(future)  # type: (str, ClientRes)
  File "/home/namvq/.cache/pypoetry/virtualenvs/niid-bench-orV17zke-py3.10/lib/python3.10/site-packages/ray/_private/auto_init_hook.py", line 24, in auto_init_wrapper
    return fn(*args, **kwargs)
  File "/home/namvq/.cache/pypoetry/virtualenvs/niid-bench-orV17zke-py3.10/lib/python3.10/site-packages/ray/_private/client_mode_hook.py", line 103, in wrapper
    return func(*args, **kwargs)
  File "/home/namvq/.cache/pypoetry/virtualenvs/niid-bench-orV17zke-py3.10/lib/python3.10/site-packages/ray/_private/worker.py", line 2524, in get
    raise value.as_instanceof_cause()
ray.exceptions.RayTaskError(ClientException): [36mray::DefaultActor.run()[39m (pid=57299, ip=172.16.1.8, actor_id=a0d91e71b45217e02a31afde01000000, repr=<flwr.simulation.ray_transport.ray_actor.DefaultActor object at 0x79451030b130>)
  File "/home/namvq/.cache/pypoetry/virtualenvs/niid-bench-orV17zke-py3.10/lib/python3.10/site-packages/flwr/simulation/ray_transport/ray_client_proxy.py", line 196, in fit
    return maybe_call_fit(
  File "/home/namvq/.cache/pypoetry/virtualenvs/niid-bench-orV17zke-py3.10/lib/python3.10/site-packages/flwr/client/client.py", line 217, in maybe_call_fit
    return client.fit(fit_ins)
  File "/home/namvq/.cache/pypoetry/virtualenvs/niid-bench-orV17zke-py3.10/lib/python3.10/site-packages/flwr/client/app.py", line 333, in _fit
    results = self.numpy_client.fit(parameters, ins.config)  # type: ignore
  File "/media/namvq/Data/code_flwr/niid_custom/niid_bench/niid_bench/client_fedprox.py", line 55, in fit
    self.set_parameters(parameters)
  File "/media/namvq/Data/code_flwr/niid_custom/niid_bench/niid_bench/client_fedprox.py", line 50, in set_parameters
    state_dict = OrderedDict({k: torch.from_numpy(np.copy(v)) for k, v in params_dict})
  File "/media/namvq/Data/code_flwr/niid_custom/niid_bench/niid_bench/client_fedprox.py", line 50, in <dictcomp>
    state_dict = OrderedDict({k: torch.from_numpy(np.copy(v)) for k, v in params_dict})
NameError: name 'np' is not defined

The above exception was the direct cause of the following exception:

[36mray::DefaultActor.run()[39m (pid=57299, ip=172.16.1.8, actor_id=a0d91e71b45217e02a31afde01000000, repr=<flwr.simulation.ray_transport.ray_actor.DefaultActor object at 0x79451030b130>)
  File "/home/namvq/.cache/pypoetry/virtualenvs/niid-bench-orV17zke-py3.10/lib/python3.10/site-packages/flwr/simulation/ray_transport/ray_actor.py", line 72, in run
    raise ClientException(str(message)) from ex
flwr.simulation.ray_transport.ray_actor.ClientException: 
>>>>>>>A ClientException occurred.('\n\tSomething went wrong when running your client workload.\n\tClient 51 crashed when the DefaultActor was running its workload.\n\tException triggered on the client side: Traceback (most recent call last):\n  File "/home/namvq/.cache/pypoetry/virtualenvs/niid-bench-orV17zke-py3.10/lib/python3.10/site-packages/flwr/simulation/ray_transport/ray_actor.py", line 60, in run\n    job_results = job_fn()\n  File "/home/namvq/.cache/pypoetry/virtualenvs/niid-bench-orV17zke-py3.10/lib/python3.10/site-packages/flwr/simulation/ray_transport/ray_client_proxy.py", line 196, in fit\n    return maybe_call_fit(\n  File "/home/namvq/.cache/pypoetry/virtualenvs/niid-bench-orV17zke-py3.10/lib/python3.10/site-packages/flwr/client/client.py", line 217, in maybe_call_fit\n    return client.fit(fit_ins)\n  File "/home/namvq/.cache/pypoetry/virtualenvs/niid-bench-orV17zke-py3.10/lib/python3.10/site-packages/flwr/client/app.py", line 333, in _fit\n    results = self.numpy_client.fit(parameters, ins.config)  # type: ignore\n  File "/media/namvq/Data/code_flwr/niid_custom/niid_bench/niid_bench/client_fedprox.py", line 55, in fit\n    self.set_parameters(parameters)\n  File "/media/namvq/Data/code_flwr/niid_custom/niid_bench/niid_bench/client_fedprox.py", line 50, in set_parameters\n    state_dict = OrderedDict({k: torch.from_numpy(np.copy(v)) for k, v in params_dict})\n  File "/media/namvq/Data/code_flwr/niid_custom/niid_bench/niid_bench/client_fedprox.py", line 50, in <dictcomp>\n    state_dict = OrderedDict({k: torch.from_numpy(np.copy(v)) for k, v in params_dict})\nNameError: name \'np\' is not defined\n',)

[2024-11-28 17:48:52,185][flwr][ERROR] - [36mray::DefaultActor.run()[39m (pid=57299, ip=172.16.1.8, actor_id=a0d91e71b45217e02a31afde01000000, repr=<flwr.simulation.ray_transport.ray_actor.DefaultActor object at 0x79451030b130>)
  File "/home/namvq/.cache/pypoetry/virtualenvs/niid-bench-orV17zke-py3.10/lib/python3.10/site-packages/flwr/simulation/ray_transport/ray_client_proxy.py", line 196, in fit
    return maybe_call_fit(
  File "/home/namvq/.cache/pypoetry/virtualenvs/niid-bench-orV17zke-py3.10/lib/python3.10/site-packages/flwr/client/client.py", line 217, in maybe_call_fit
    return client.fit(fit_ins)
  File "/home/namvq/.cache/pypoetry/virtualenvs/niid-bench-orV17zke-py3.10/lib/python3.10/site-packages/flwr/client/app.py", line 333, in _fit
    results = self.numpy_client.fit(parameters, ins.config)  # type: ignore
  File "/media/namvq/Data/code_flwr/niid_custom/niid_bench/niid_bench/client_fedprox.py", line 55, in fit
    self.set_parameters(parameters)
  File "/media/namvq/Data/code_flwr/niid_custom/niid_bench/niid_bench/client_fedprox.py", line 50, in set_parameters
    state_dict = OrderedDict({k: torch.from_numpy(np.copy(v)) for k, v in params_dict})
  File "/media/namvq/Data/code_flwr/niid_custom/niid_bench/niid_bench/client_fedprox.py", line 50, in <dictcomp>
    state_dict = OrderedDict({k: torch.from_numpy(np.copy(v)) for k, v in params_dict})
NameError: name 'np' is not defined

The above exception was the direct cause of the following exception:

[36mray::DefaultActor.run()[39m (pid=57299, ip=172.16.1.8, actor_id=a0d91e71b45217e02a31afde01000000, repr=<flwr.simulation.ray_transport.ray_actor.DefaultActor object at 0x79451030b130>)
  File "/home/namvq/.cache/pypoetry/virtualenvs/niid-bench-orV17zke-py3.10/lib/python3.10/site-packages/flwr/simulation/ray_transport/ray_actor.py", line 72, in run
    raise ClientException(str(message)) from ex
flwr.simulation.ray_transport.ray_actor.ClientException: 
>>>>>>>A ClientException occurred.('\n\tSomething went wrong when running your client workload.\n\tClient 51 crashed when the DefaultActor was running its workload.\n\tException triggered on the client side: Traceback (most recent call last):\n  File "/home/namvq/.cache/pypoetry/virtualenvs/niid-bench-orV17zke-py3.10/lib/python3.10/site-packages/flwr/simulation/ray_transport/ray_actor.py", line 60, in run\n    job_results = job_fn()\n  File "/home/namvq/.cache/pypoetry/virtualenvs/niid-bench-orV17zke-py3.10/lib/python3.10/site-packages/flwr/simulation/ray_transport/ray_client_proxy.py", line 196, in fit\n    return maybe_call_fit(\n  File "/home/namvq/.cache/pypoetry/virtualenvs/niid-bench-orV17zke-py3.10/lib/python3.10/site-packages/flwr/client/client.py", line 217, in maybe_call_fit\n    return client.fit(fit_ins)\n  File "/home/namvq/.cache/pypoetry/virtualenvs/niid-bench-orV17zke-py3.10/lib/python3.10/site-packages/flwr/client/app.py", line 333, in _fit\n    results = self.numpy_client.fit(parameters, ins.config)  # type: ignore\n  File "/media/namvq/Data/code_flwr/niid_custom/niid_bench/niid_bench/client_fedprox.py", line 55, in fit\n    self.set_parameters(parameters)\n  File "/media/namvq/Data/code_flwr/niid_custom/niid_bench/niid_bench/client_fedprox.py", line 50, in set_parameters\n    state_dict = OrderedDict({k: torch.from_numpy(np.copy(v)) for k, v in params_dict})\n  File "/media/namvq/Data/code_flwr/niid_custom/niid_bench/niid_bench/client_fedprox.py", line 50, in <dictcomp>\n    state_dict = OrderedDict({k: torch.from_numpy(np.copy(v)) for k, v in params_dict})\nNameError: name \'np\' is not defined\n',)
[2024-11-28 17:48:52,185][flwr][DEBUG] - fit_round 1 received 0 results and 2 failures
